<?xml version="1.0" ?>
<!-- =================================================================================== -->
<!-- |    This document was autogenerated by xacro from rosemarie.xacro                | -->
<!-- |    EDITING THIS FILE BY HAND IS NOT RECOMMENDED                                 | -->
<!-- =================================================================================== -->
<robot name="rosemarie" xmlns:xacro="http://www.ros.org/wiki/xacro">
  <material name="Kuka/DarkGrey">
    <color rgba="0.3 0.3 0.3 1.0"/>
  </material>
  <material name="Kuka/LightGrey">
    <color rgba="0.8 0.8 0.8 1.0"/>
  </material>
  <material name="Kuka/Red">
    <color rgba="0.3 0.3 0.3 1.0"/>
  </material>
  <material name="Kuka/Black">
    <color rgba="0 0 0 1.0"/>
  </material>
  <material name="Kuka/Orange">
    <!--<color rgba="1.0 0.487 0 1.0"/>-->
    <color rgba="0.8 0.4 0.4 1.0"/>
  </material>
  <material name="Kuka/Silver">
    <color rgba="1.0 1.0 1.0 1.0"/>
  </material>
  <material name="Kuka/Grey">
    <color rgba="0.7 0.7 0.7 1.0"/>
  </material>
  <material name="Kuka/Blue">
    <color rgba="0.0 0.0 0.8 1.0"/>
  </material>
  <!-- reflex to stiffness -->
  <!-- Base Link /-->
  <link name="base_link">
    <visual>
      <geometry>
        <mesh filename="package://rosemarie_description/meshes/grundgestell.dae"/>
      </geometry>
    </visual>
    <collision>
      <geometry>
        <mesh filename="package://rosemarie_description/meshes/grundgestell_collision_1.stl"/>
      </geometry>
    </collision>
    <inertial>
      <mass value="145.02"/>
      <origin xyz="-.02 .01 .45"/>
      <inertia ixx="45.23" ixy="0.48" ixz="1.92" iyy="51.08" iyz="-0.41" izz="15.64"/>
    </inertial>
  </link>
  <!-- Pan Joint /-->
  <joint name="head_pan_joint" type="revolute">
    <origin rpy="0 0 0" xyz=".405 0 1.476"/>
    <axis xyz="0 0 -1"/>
    <limit effort="30" lower="-1.57079632679" upper="1.57079632679" velocity="4.18879020479"/>
    <parent link="base_link"/>
    <child link="head_pan_link"/>
  </joint>
  <!-- Pan Link /-->
  <link name="head_pan_link">
    <inertial>
      <mass value="2.77"/>
      <origin xyz="0 -.2 .08"/>
      <inertia ixx="0.03" ixy="0.0" ixz="0.0" iyy="0.02" iyz="0.0" izz="0.01"/>
    </inertial>
    <visual>
      <geometry>
        <mesh filename="package://schunk_pw70/meshes/kopf_pan_2.dae"/>
      </geometry>
    </visual>
    <collision>
      <origin xyz="0 0 .08"/>
      <geometry>
        <box size=".07 .2 .16"/>
      </geometry>
    </collision>
  </link>
  <!-- Tilt Joint /-->
  <joint name="head_tilt_joint" type="revolute">
    <origin rpy="0 0 0" xyz="0 0 .1"/>
    <axis xyz="0 -1 0"/>
    <limit effort="30" lower="-1.57079632679" upper="1.57079632679" velocity="6.28318530718"/>
    <parent link="head_pan_link"/>
    <child link="head_tilt_link"/>
  </joint>
  <!-- Tilt Link /-->
  <link name="head_tilt_link">
    <inertial>
      <mass value="0.545"/>
      <origin xyz="0 .02 .02"/>
      <inertia ixx="0.006" ixy="0.0" ixz="0.0" iyy="0.004" iyz="0.0" izz="0.002"/>
    </inertial>
    <visual>
      <origin xyz="0 0 0"/>
      <geometry>
        <mesh filename="package://schunk_pw70/meshes/kopf_tilt_2.dae"/>
      </geometry>
    </visual>
    <collision>
      <origin xyz="0 0 .035"/>
      <geometry>
        <box size=".07 .2 .07"/>
      </geometry>
    </collision>
  </link>
  <!-- Joint /-->
  <joint name="kinect_joint" type="fixed">
    <origin rpy="0 0 0" xyz="0 0 .07"/>
    <origin rpy="0 0 0" xyz="0 0 0"/>
    <parent link="head_tilt_link"/>
    <child link="kinect"/>
  </joint>
  <!-- Link /-->
  <link name="kinect">
    <visual>
      <geometry>
        <mesh filename="package://rosemarie_description/meshes/kinectkamera.dae"/>
      </geometry>
    </visual>
    <collision>
      <origin xyz="0 0 .25"/>
      <geometry>
        <box size=".07 .2 .05"/>
      </geometry>
    </collision>
    <inertial>
      <mass value="0.3"/>
      <origin xyz="0 0 .02"/>
      <inertia ixx="0.01" ixy="0.0" ixz="0.0" iyy="0.01" iyz="0.0" izz="0.01"/>
    </inertial>
  </link>
  <!-- First (shoulder) element of the arm. Fixed to its parent. -->
  <joint name="base_link_left_arm_base_joint" type="fixed">
    <origin rpy="2.15809962 -0.447832275 -2.86056" xyz=".405 .0967 1.42"/>
    <origin rpy="0 0 0" xyz="0 0 0"/>
    <parent link="base_link"/>
    <child link="left_arm_base_link"/>
  </joint>
  <link name="left_arm_base_link">
    <inertial>
      <mass value="2.0"/>
      <origin xyz="0 0 0.055"/>
      <inertia ixx="0.00381666666667" ixy="0" ixz="0" iyy="0.0036" iyz="0" izz="0.00381666666667"/>
    </inertial>
    <visual>
      <origin rpy="0 0 3.14159265359" xyz="0 0 0"/>
      <geometry>
        <mesh filename="package://lwr_description/meshes/base.STL"/>
      </geometry>
      <material name="Kuka/Orange"/>
    </visual>
    <collision>
      <origin rpy="0 0 3.14159265359" xyz="0 0 0.055"/>
      <geometry>
        <!-- <mesh filename="package://lwr_description/meshes/convex/arm_base_convex.stl"/> -->
        <cylinder length="0.11" radius="0.07"/>
      </geometry>
    </collision>
  </link>
  <!-- Second segment of the arm. Joint along z-axis -->
  <joint name="left_arm_0_joint" type="revolute">
    <origin rpy="0 0 0" xyz="0 0 0.11"/>
    <axis xyz="0 0 1"/>
    <limit effort="176" lower="-2.96705972839" upper="2.96705972839" velocity="1.91986217719"/>
    <dynamics damping="1.0" friction="10.0"/>
    <parent link="left_arm_base_link"/>
    <child link="left_arm_1_link"/>
  </joint>
  <joint name="left_arm_0_joint_stiffness" type="revolute">
    <axis xyz="0 0 1"/>
    <limit effort="0" lower="0" upper="5000" velocity="20000"/>
    <safety_controller k_position="30" k_velocity="30" soft_lower_limit="0" soft_upper_limit="5000"/>
    <parent link="left_arm_base_link"/>
    <child link="left_arm_1_link_dummy"/>
    <origin rpy="0 0 0"/>
  </joint>
  <link name="left_arm_1_link_dummy"/>
  <link name="left_arm_1_link">
    <inertial>
      <mass value="2.0"/>
      <origin rpy="0 0 0" xyz="0 -0.06 0.130"/>
      <inertia ixx="0.0136666666667" ixy="0" ixz="0" iyy="0.003" iyz="0" izz="0.0118666666667"/>
    </inertial>
    <visual>
      <origin rpy="0 0 3.14159265359" xyz="0 0 -0.008"/>
      <geometry>
        <mesh filename="package://lwr_description/meshes/link_1.STL"/>
      </geometry>
      <material name="Kuka/Orange"/>
    </visual>
    <collision>
      <origin rpy="0 0 0" xyz="0 0 0.0"/>
      <geometry>
        <!--mesh filename="package://lwr_description/meshes/convex/arm_segment_a_convex.stl"/-->
        <sphere radius="0.07"/>
      </geometry>
    </collision>
    <collision>
      <origin rpy="0 0 0" xyz="0 0.06 0.2"/>
      <geometry>
        <sphere radius="0.07"/>
      </geometry>
    </collision>
    <collision>
      <origin rpy="-0.291 0 0" xyz="0 0.03 0.1"/>
      <geometry>
        <cylinder length="0.208" radius="0.07"/>
      </geometry>
    </collision>
  </link>
  <!-- Third segment of the arm. Joint along y-axis -->
  <joint name="left_arm_1_joint" type="revolute">
    <origin rpy="0 0 0" xyz="0 0 0.2005"/>
    <axis xyz="0 -1 0"/>
    <limit effort="176" lower="-2.09439510239" upper="2.09439510239" velocity="1.91986217719"/>
    <dynamics damping="1.0" friction="10.0"/>
    <parent link="left_arm_1_link"/>
    <child link="left_arm_2_link"/>
  </joint>
  <joint name="left_arm_1_joint_stiffness" type="revolute">
    <axis rpy="0 0 0" xyz="0 0 1"/>
    <limit effort="0" lower="0" upper="5000" velocity="20000"/>
    <safety_controller k_position="30" k_velocity="30" soft_lower_limit="0" soft_upper_limit="5000"/>
    <parent link="left_arm_1_link"/>
    <child link="left_arm_2_link_dummy"/>
    <origin rpy="0 0 0"/>
  </joint>
  <link name="left_arm_2_link_dummy"/>
  <link name="left_arm_2_link">
    <inertial>
      <mass value="2.0"/>
      <origin rpy="0 0 0" xyz="0 0.06 0.07"/>
      <inertia ixx="0.0136666666667" ixy="0" ixz="0" iyy="0.003" iyz="0" izz="0.0118666666667"/>
    </inertial>
    <visual>
      <origin rpy="0 0 3.14159265359" xyz="0 0 0.0"/>
      <geometry>
        <mesh filename="package://lwr_description/meshes/link_2.STL"/>
      </geometry>
      <material name="Kuka/Orange"/>
    </visual>
    <collision>
      <origin rpy="0 0 0" xyz="0 0 0.2"/>
      <geometry>
        <!--mesh filename="package://lwr_description/meshes/convex/arm_segment_b_convex.stl"/-->
        <sphere radius="0.07"/>
      </geometry>
    </collision>
    <collision>
      <origin rpy="0 0 0" xyz="0 -0.06 0.0"/>
      <geometry>
        <sphere radius="0.07"/>
      </geometry>
    </collision>
    <collision>
      <origin rpy="-0.291 0 0" xyz="0 -0.03 0.1"/>
      <geometry>
        <cylinder length="0.208" radius="0.07"/>
      </geometry>
    </collision>
  </link>
  <!-- Fourth element of the arm. z-axis -->
  <joint name="left_arm_2_joint" type="revolute">
    <origin rpy="0 0 0" xyz="0 0 0.20"/>
    <axis xyz="0 0 1"/>
    <limit effort="100" lower="-2.96705972839" upper="2.96705972839" velocity="2.23402144255"/>
    <dynamics damping="1.0" friction="10.0"/>
    <parent link="left_arm_2_link"/>
    <child link="left_arm_3_link"/>
  </joint>
  <joint name="left_arm_2_joint_stiffness" type="revolute">
    <axis rpy="0 0 0" xyz="0 0 1"/>
    <limit effort="0" lower="0" upper="5000" velocity="20000"/>
    <safety_controller k_position="30" k_velocity="30" soft_lower_limit="0" soft_upper_limit="5000"/>
    <parent link="left_arm_2_link"/>
    <child link="left_arm_3_link_dummy"/>
    <origin rpy="0 0 0"/>
  </joint>
  <link name="left_arm_3_link_dummy"/>
  <link name="left_arm_3_link">
    <inertial>
      <mass value="2.0"/>
      <origin rpy="0 0 0" xyz="0 0.06 0.130"/>
      <inertia ixx="0.0136666666667" ixy="0" ixz="0" iyy="0.003" iyz="0" izz="0.0118666666667"/>
    </inertial>
    <visual>
      <origin rpy="0 0 3.14159265359" xyz="0 0 -0.008"/>
      <geometry>
        <mesh filename="package://lwr_description/meshes/link_3.STL"/>
      </geometry>
      <material name="Kuka/Orange"/>
    </visual>
    <collision>
      <origin rpy="0 0 0" xyz="0 0 0.0"/>
      <geometry>
        <!--mesh filename="package://lwr_description/meshes/convex/arm_segment_a_convex.stl"/-->
        <sphere radius="0.07"/>
      </geometry>
    </collision>
    <collision>
      <origin rpy="0 0 0" xyz="0 -0.06 0.2"/>
      <geometry>
        <sphere radius="0.07"/>
      </geometry>
    </collision>
    <collision>
      <origin rpy="0.291 0 0" xyz="0 -0.03 0.1"/>
      <geometry>
        <cylinder length="0.208" radius="0.07"/>
      </geometry>
    </collision>
  </link>
  <!-- fifth element of the arm. x-axis -->
  <joint name="left_arm_3_joint" type="revolute">
    <origin rpy="0 0 0" xyz="0 0 0.20"/>
    <axis xyz="0 1 0"/>
    <limit effort="100" lower="-2.09439510239" upper="2.09439510239" velocity="2.23402144255"/>
    <dynamics damping="1.0" friction="10.0"/>
    <parent link="left_arm_3_link"/>
    <child link="left_arm_4_link"/>
  </joint>
  <joint name="left_arm_3_joint_stiffness" type="revolute">
    <axis rpy="0 0 0" xyz="0 0 1"/>
    <limit effort="0" lower="0" upper="5000" velocity="20000"/>
    <safety_controller k_position="30" k_velocity="30" soft_lower_limit="0" soft_upper_limit="5000"/>
    <parent link="left_arm_3_link"/>
    <child link="left_arm_4_link_dummy"/>
    <origin rpy="0 0 0"/>
  </joint>
  <link name="left_arm_4_link_dummy"/>
  <link name="left_arm_4_link">
    <inertial>
      <mass value="2.0"/>
      <origin rpy="0 0 0" xyz="0 -0.06 0.07"/>
      <inertia ixx="0.0136666666667" ixy="0" ixz="0" iyy="0.003" iyz="0" izz="0.0118666666667"/>
    </inertial>
    <visual>
      <origin rpy="0 0 3.14159265359" xyz="0 0 0.0"/>
      <geometry>
        <mesh filename="package://lwr_description/meshes/link_4.STL"/>
      </geometry>
      <material name="Kuka/Orange"/>
    </visual>
    <collision>
      <origin rpy="0 0 0" xyz="0 0 0.2"/>
      <geometry>
        <!--mesh filename="package://lwr_description/meshes/convex/arm_segment_b_convex.stl"/-->
        <sphere radius="0.07"/>
      </geometry>
    </collision>
    <collision>
      <origin rpy="0 0 0" xyz="0 0.06 0.0"/>
      <geometry>
        <sphere radius="0.07"/>
      </geometry>
    </collision>
    <collision>
      <origin rpy="0.291 0 0" xyz="0 0.03 0.1"/>
      <geometry>
        <cylinder length="0.208" radius="0.07"/>
      </geometry>
    </collision>
  </link>
  <!-- Sixth element of the arm. z-axis -->
  <joint name="left_arm_4_joint" type="revolute">
    <origin rpy="0 0 0" xyz="0 0 0.20"/>
    <axis xyz="0 0 1"/>
    <limit effort="100" lower="-2.96705972839" upper="2.96705972839" velocity="3.56047167407"/>
    <dynamics damping="1.0" friction="10.0"/>
    <parent link="left_arm_4_link"/>
    <child link="left_arm_5_link"/>
  </joint>
  <joint name="left_arm_4_joint_stiffness" type="revolute">
    <axis rpy="0 0 0" xyz="0 0 1"/>
    <limit effort="0" lower="0" upper="5000" velocity="20000"/>
    <safety_controller k_position="30" k_velocity="30" soft_lower_limit="0" soft_upper_limit="5000"/>
    <parent link="left_arm_4_link"/>
    <child link="left_arm_5_link_dummy"/>
    <origin rpy="0 0 0"/>
  </joint>
  <link name="left_arm_5_link_dummy"/>
  <link name="left_arm_5_link">
    <inertial>
      <mass value="2.0"/>
      <origin rpy="0 0 0" xyz="0 0 0.124"/>
      <inertia ixx="0.0126506666667" ixy="0" ixz="0" iyy="0.003" iyz="0" izz="0.0108506666667"/>
    </inertial>
    <visual>
      <origin rpy="0 0 3.14159265359" xyz="0 0 -0.008"/>
      <geometry name="left_arm_5_geom">
        <mesh filename="package://lwr_description/meshes/link_5.STL"/>
      </geometry>
      <material name="Kuka/Orange"/>
    </visual>
    <collision>
      <origin rpy="0 0 0" xyz="0 0 0.0"/>
      <geometry>
        <!--mesh filename="package://lwr_description/meshes/convex/arm_segment_last_convex.stl"/-->
        <sphere radius="0.07"/>
      </geometry>
    </collision>
    <collision>
      <origin rpy="0 0 0" xyz="0 0.04 0.19"/>
      <geometry>
        <sphere radius="0.07"/>
      </geometry>
    </collision>
    <collision>
      <origin rpy="-0.207 0 0" xyz="0 0.02 0.095"/>
      <geometry>
        <cylinder length="0.198" radius="0.07"/>
      </geometry>
    </collision>
  </link>
  <!-- Seventh element of the arm. z-axis -->
  <joint name="left_arm_5_joint" type="revolute">
    <origin rpy="0 0 0" xyz="0 0 0.19"/>
    <axis xyz="0 -1 0"/>
    <limit effort="38" lower="-2.09439510239" upper="2.09439510239" velocity="3.21140582367"/>
    <dynamics damping="1.0" friction="10.0"/>
    <parent link="left_arm_5_link"/>
    <child link="left_arm_6_link"/>
  </joint>
  <joint name="left_arm_5_joint_stiffness" type="revolute">
    <axis rpy="0 0 0" xyz="0 0 1"/>
    <limit effort="0" lower="0" upper="5000" velocity="20000"/>
    <safety_controller k_position="30" k_velocity="30" soft_lower_limit="0" soft_upper_limit="5000"/>
    <parent link="left_arm_5_link"/>
    <child link="left_arm_6_link_dummy"/>
    <origin rpy="0 0 0"/>
  </joint>
  <link name="left_arm_6_link_dummy"/>
  <link name="left_arm_6_link">
    <inertial>
      <mass value="0.2"/>
      <origin rpy="0 0 0" xyz="0 0 0.0625"/>
      <inertia ixx="0.000520833333333" ixy="0" ixz="0" iyy="0.000520833333333" iyz="0" izz="0.000520833333333"/>
    </inertial>
    <visual>
      <origin rpy="0 0 3.14159265359" xyz="0 0 0"/>
      <geometry>
        <mesh filename="package://lwr_description/meshes/link_6.STL"/>
      </geometry>
      <material name="Kuka/Grey"/>
    </visual>
    <collision>
      <origin rpy="0 0 3.14159265359" xyz="0 0 0"/>
      <geometry>
        <mesh filename="package://lwr_description/meshes/convex/arm_wrist_convex.stl"/>
      </geometry>
    </collision>
  </link>
  <!-- Eighth element of the arm. z-axis -->
  <joint name="left_arm_6_joint" type="revolute">
    <origin rpy="0 0 0" xyz="0 0 0.078"/>
    <axis xyz="0 0 1"/>
    <limit effort="38" lower="-2.96705972839" upper="2.96705972839" velocity="3.21140582367"/>
    <dynamics damping="1.0" friction="10.0"/>
    <parent link="left_arm_6_link"/>
    <child link="left_arm_7_link"/>
  </joint>
  <joint name="left_arm_6_joint_stiffness" type="revolute">
    <axis rpy="0 0 0" xyz="0 0 1"/>
    <limit effort="0" lower="0" upper="5000" velocity="20000"/>
    <safety_controller k_position="30" k_velocity="30" soft_lower_limit="0" soft_upper_limit="5000"/>
    <parent link="left_arm_6_link"/>
    <child link="left_arm_7_link_dummy"/>
    <origin rpy="0 0 0"/>
  </joint>
  <link name="left_arm_7_link_dummy"/>
  <link name="left_arm_7_link">
    <inertial>
      <mass value="0.2"/>
      <origin xyz="0 0 0"/>
      <inertia ixx="0.0333333333333" ixy="0" ixz="0" iyy="0.0333333333333" iyz="0" izz="0.0333333333333"/>
    </inertial>
    <visual>
      <origin rpy="0 0 3.14159265359" xyz="0 0 0"/>
      <geometry>
        <mesh filename="package://lwr_description/meshes/link_7.STL"/>
      </geometry>
      <material name="Kuka/DarkGrey"/>
    </visual>
    <collision>
      <origin rpy="0 0 3.14159265359" xyz="0 0 0"/>
      <geometry>
        <cylinder length="0.05" radius="0.04"/>
      </geometry>
    </collision>
  </link>
  <gazebo>
    <plugin filename="liblwr_hw_gazebo_plugin.so" name="left_arm_lwr_hw_sim">
      <robotNamespace>left_arm</robotNamespace>
    </plugin>
  </gazebo>
  <gazebo reference="left_arm_base_link">
    <gravity>true</gravity>
    <material>Gazebo/Orange</material>
  </gazebo>
  <gazebo reference="left_arm_1_link">
    <gravity>true</gravity>
    <material>Gazebo/Orange</material>
  </gazebo>
  <gazebo reference="left_arm_2_link">
    <gravity>true</gravity>
    <material>Gazebo/Orange</material>
  </gazebo>
  <gazebo reference="left_arm_3_link">
    <gravity>true</gravity>
    <material>Gazebo/Orange</material>
  </gazebo>
  <gazebo reference="left_arm_4_link">
    <gravity>true</gravity>
    <material>Gazebo/Orange</material>
  </gazebo>
  <gazebo reference="left_arm_5_link">
    <gravity>true</gravity>
    <material>Gazebo/Orange</material>
  </gazebo>
  <gazebo reference="left_arm_6_link">
    <gravity>true</gravity>
    <material>Gazebo/Orange</material>
  </gazebo>
  <gazebo reference="left_arm_7_link">
    <gravity>true</gravity>
    <material>Gazebo/Grey</material>
  </gazebo>
  <transmission name="left_arm_0_trans">
    <type>transmission_interface/SimpleTransmission</type>
    <robotNamespace>left_arm</robotNamespace>
    <joint name="left_arm_0_joint">
      <hardwareInterface>PositionJointInterface</hardwareInterface>
      <hardwareInterface>EffortJointInterface</hardwareInterface>
    </joint>
    <actuator name="left_arm_0_motor">
      <mechanicalReduction>1</mechanicalReduction>
    </actuator>
  </transmission>
  <transmission name="left_arm_1_trans">
    <type>transmission_interface/SimpleTransmission</type>
    <robotNamespace>left_arm</robotNamespace>
    <joint name="left_arm_1_joint">
      <hardwareInterface>PositionJointInterface</hardwareInterface>
      <hardwareInterface>EffortJointInterface</hardwareInterface>
    </joint>
    <actuator name="left_arm_1_motor">
      <mechanicalReduction>1</mechanicalReduction>
    </actuator>
  </transmission>
  <transmission name="left_arm_2_trans">
    <type>transmission_interface/SimpleTransmission</type>
    <robotNamespace>left_arm</robotNamespace>
    <joint name="left_arm_2_joint">
      <hardwareInterface>PositionJointInterface</hardwareInterface>
      <hardwareInterface>EffortJointInterface</hardwareInterface>
    </joint>
    <actuator name="left_arm_2_motor">
      <mechanicalReduction>1</mechanicalReduction>
    </actuator>
  </transmission>
  <transmission name="left_arm_3_trans">
    <type>transmission_interface/SimpleTransmission</type>
    <robotNamespace>left_arm</robotNamespace>
    <joint name="left_arm_3_joint">
      <hardwareInterface>PositionJointInterface</hardwareInterface>
      <hardwareInterface>EffortJointInterface</hardwareInterface>
    </joint>
    <actuator name="left_arm_3_motor">
      <mechanicalReduction>1</mechanicalReduction>
    </actuator>
  </transmission>
  <transmission name="left_arm_4_trans">
    <type>transmission_interface/SimpleTransmission</type>
    <robotNamespace>left_arm</robotNamespace>
    <joint name="left_arm_4_joint">
      <hardwareInterface>PositionJointInterface</hardwareInterface>
      <hardwareInterface>EffortJointInterface</hardwareInterface>
    </joint>
    <actuator name="left_arm_4_motor">
      <mechanicalReduction>1</mechanicalReduction>
    </actuator>
  </transmission>
  <transmission name="left_arm_5_trans">
    <type>transmission_interface/SimpleTransmission</type>
    <robotNamespace>left_arm</robotNamespace>
    <joint name="left_arm_5_joint">
      <hardwareInterface>PositionJointInterface</hardwareInterface>
      <hardwareInterface>EffortJointInterface</hardwareInterface>
    </joint>
    <actuator name="left_arm_5_motor">
      <mechanicalReduction>1</mechanicalReduction>
    </actuator>
  </transmission>
  <transmission name="left_arm_6_trans">
    <type>transmission_interface/SimpleTransmission</type>
    <robotNamespace>left_arm</robotNamespace>
    <joint name="left_arm_6_joint">
      <hardwareInterface>PositionJointInterface</hardwareInterface>
      <hardwareInterface>EffortJointInterface</hardwareInterface>
    </joint>
    <actuator name="left_arm_6_motor">
      <mechanicalReduction>1</mechanicalReduction>
    </actuator>
  </transmission>
  <!-- First (shoulder) element of the arm. Fixed to its parent. -->
  <joint name="base_link_right_arm_base_joint" type="fixed">
    <origin rpy="-2.15809962 -0.447832275 -2.86056" xyz=".405 -.0967 1.42"/>
    <origin rpy="0 0 0" xyz="0 0 0"/>
    <parent link="base_link"/>
    <child link="right_arm_base_link"/>
  </joint>
  <link name="right_arm_base_link">
    <inertial>
      <mass value="2.0"/>
      <origin xyz="0 0 0.055"/>
      <inertia ixx="0.00381666666667" ixy="0" ixz="0" iyy="0.0036" iyz="0" izz="0.00381666666667"/>
    </inertial>
    <visual>
      <origin rpy="0 0 3.14159265359" xyz="0 0 0"/>
      <geometry>
        <mesh filename="package://lwr_description/meshes/base.STL"/>
      </geometry>
      <material name="Kuka/Orange"/>
    </visual>
    <collision>
      <origin rpy="0 0 3.14159265359" xyz="0 0 0.055"/>
      <geometry>
        <!-- <mesh filename="package://lwr_description/meshes/convex/arm_base_convex.stl"/> -->
        <cylinder length="0.11" radius="0.07"/>
      </geometry>
    </collision>
  </link>
  <!-- Second segment of the arm. Joint along z-axis -->
  <joint name="right_arm_0_joint" type="revolute">
    <origin rpy="0 0 0" xyz="0 0 0.11"/>
    <axis xyz="0 0 1"/>
    <limit effort="176" lower="-2.96705972839" upper="2.96705972839" velocity="1.91986217719"/>
    <dynamics damping="1.0" friction="10.0"/>
    <parent link="right_arm_base_link"/>
    <child link="right_arm_1_link"/>
  </joint>
  <joint name="right_arm_0_joint_stiffness" type="revolute">
    <axis xyz="0 0 1"/>
    <limit effort="0" lower="0" upper="5000" velocity="20000"/>
    <safety_controller k_position="30" k_velocity="30" soft_lower_limit="0" soft_upper_limit="5000"/>
    <parent link="right_arm_base_link"/>
    <child link="right_arm_1_link_dummy"/>
    <origin rpy="0 0 0"/>
  </joint>
  <link name="right_arm_1_link_dummy"/>
  <link name="right_arm_1_link">
    <inertial>
      <mass value="2.0"/>
      <origin rpy="0 0 0" xyz="0 -0.06 0.130"/>
      <inertia ixx="0.0136666666667" ixy="0" ixz="0" iyy="0.003" iyz="0" izz="0.0118666666667"/>
    </inertial>
    <visual>
      <origin rpy="0 0 3.14159265359" xyz="0 0 -0.008"/>
      <geometry>
        <mesh filename="package://lwr_description/meshes/link_1.STL"/>
      </geometry>
      <material name="Kuka/Orange"/>
    </visual>
    <collision>
      <origin rpy="0 0 0" xyz="0 0 0.0"/>
      <geometry>
        <!--mesh filename="package://lwr_description/meshes/convex/arm_segment_a_convex.stl"/-->
        <sphere radius="0.07"/>
      </geometry>
    </collision>
    <collision>
      <origin rpy="0 0 0" xyz="0 0.06 0.2"/>
      <geometry>
        <sphere radius="0.07"/>
      </geometry>
    </collision>
    <collision>
      <origin rpy="-0.291 0 0" xyz="0 0.03 0.1"/>
      <geometry>
        <cylinder length="0.208" radius="0.07"/>
      </geometry>
    </collision>
  </link>
  <!-- Third segment of the arm. Joint along y-axis -->
  <joint name="right_arm_1_joint" type="revolute">
    <origin rpy="0 0 0" xyz="0 0 0.2005"/>
    <axis xyz="0 -1 0"/>
    <limit effort="176" lower="-2.09439510239" upper="2.09439510239" velocity="1.91986217719"/>
    <dynamics damping="1.0" friction="10.0"/>
    <parent link="right_arm_1_link"/>
    <child link="right_arm_2_link"/>
  </joint>
  <joint name="right_arm_1_joint_stiffness" type="revolute">
    <axis xyz="0 0 1"/>
    <limit effort="0" lower="0" upper="5000" velocity="20000"/>
    <safety_controller k_position="30" k_velocity="30" soft_lower_limit="0" soft_upper_limit="5000"/>
    <parent link="right_arm_1_link"/>
    <child link="right_arm_2_link_dummy"/>
    <origin rpy="0 0 0"/>
  </joint>
  <link name="right_arm_2_link_dummy"/>
  <link name="right_arm_2_link">
    <inertial>
      <mass value="2.0"/>
      <origin rpy="0 0 0" xyz="0 0.06 0.07"/>
      <inertia ixx="0.0136666666667" ixy="0" ixz="0" iyy="0.003" iyz="0" izz="0.0118666666667"/>
    </inertial>
    <visual>
      <origin rpy="0 0 3.14159265359" xyz="0 0 0.0"/>
      <geometry>
        <mesh filename="package://lwr_description/meshes/link_2.STL"/>
      </geometry>
      <material name="Kuka/Orange"/>
    </visual>
    <collision>
      <origin rpy="0 0 0" xyz="0 0 0.2"/>
      <geometry>
        <!--mesh filename="package://lwr_description/meshes/convex/arm_segment_b_convex.stl"/-->
        <sphere radius="0.07"/>
      </geometry>
    </collision>
    <collision>
      <origin rpy="0 0 0" xyz="0 -0.06 0.0"/>
      <geometry>
        <sphere radius="0.07"/>
      </geometry>
    </collision>
    <collision>
      <origin rpy="-0.291 0 0" xyz="0 -0.03 0.1"/>
      <geometry>
        <cylinder length="0.208" radius="0.07"/>
      </geometry>
    </collision>
  </link>
  <!-- Fourth element of the arm. z-axis -->
  <joint name="right_arm_2_joint" type="revolute">
    <origin rpy="0 0 0" xyz="0 0 0.20"/>
    <axis xyz="0 0 1"/>
    <limit effort="100" lower="-2.96705972839" upper="2.96705972839" velocity="2.23402144255"/>
    <dynamics damping="1.0" friction="10.0"/>
    <parent link="right_arm_2_link"/>
    <child link="right_arm_3_link"/>
  </joint>
  <joint name="right_arm_2_joint_stiffness" type="revolute">
    <axis xyz="0 0 1"/>
    <limit effort="0" lower="0" upper="5000" velocity="20000"/>
    <safety_controller k_position="30" k_velocity="30" soft_lower_limit="0" soft_upper_limit="5000"/>
    <parent link="right_arm_2_link"/>
    <child link="right_arm_3_link_dummy"/>
    <origin rpy="0 0 0"/>
  </joint>
  <link name="right_arm_3_link_dummy"/>
  <link name="right_arm_3_link">
    <inertial>
      <mass value="2.0"/>
      <origin rpy="0 0 0" xyz="0 0.06 0.130"/>
      <inertia ixx="0.0136666666667" ixy="0" ixz="0" iyy="0.003" iyz="0" izz="0.0118666666667"/>
    </inertial>
    <visual>
      <origin rpy="0 0 3.14159265359" xyz="0 0 -0.008"/>
      <geometry>
        <mesh filename="package://lwr_description/meshes/link_3.STL"/>
      </geometry>
      <material name="Kuka/Orange"/>
    </visual>
    <collision>
      <origin rpy="0 0 0" xyz="0 0 0.0"/>
      <geometry>
        <!--mesh filename="package://lwr_description/meshes/convex/arm_segment_a_convex.stl"/-->
        <sphere radius="0.07"/>
      </geometry>
    </collision>
    <collision>
      <origin rpy="0 0 0" xyz="0 -0.06 0.2"/>
      <geometry>
        <sphere radius="0.07"/>
      </geometry>
    </collision>
    <collision>
      <origin rpy="0.291 0 0" xyz="0 -0.03 0.1"/>
      <geometry>
        <cylinder length="0.208" radius="0.07"/>
      </geometry>
    </collision>
  </link>
  <!-- fifth element of the arm. x-axis -->
  <joint name="right_arm_3_joint" type="revolute">
    <origin rpy="0 0 0" xyz="0 0 0.20"/>
    <axis xyz="0 1 0"/>
    <limit effort="100" lower="-2.09439510239" upper="2.09439510239" velocity="2.23402144255"/>
    <dynamics damping="1.0" friction="10.0"/>
    <parent link="right_arm_3_link"/>
    <child link="right_arm_4_link"/>
  </joint>
  <joint name="right_arm_3_joint_stiffness" type="revolute">
    <axis xyz="0 0 1"/>
    <limit effort="0" lower="0" upper="5000" velocity="20000"/>
    <safety_controller k_position="30" k_velocity="30" soft_lower_limit="0" soft_upper_limit="5000"/>
    <parent link="right_arm_3_link"/>
    <child link="right_arm_4_link_dummy"/>
    <origin rpy="0 0 0"/>
  </joint>
  <link name="right_arm_4_link_dummy"/>
  <link name="right_arm_4_link">
    <inertial>
      <mass value="2.0"/>
      <origin rpy="0 0 0" xyz="0 -0.06 0.07"/>
      <inertia ixx="0.0136666666667" ixy="0" ixz="0" iyy="0.003" iyz="0" izz="0.0118666666667"/>
    </inertial>
    <visual>
      <origin rpy="0 0 3.14159265359" xyz="0 0 0.0"/>
      <geometry>
        <mesh filename="package://lwr_description/meshes/link_4.STL"/>
      </geometry>
      <material name="Kuka/Orange"/>
    </visual>
    <collision>
      <origin rpy="0 0 0" xyz="0 0 0.2"/>
      <geometry>
        <!--mesh filename="package://lwr_description/meshes/convex/arm_segment_b_convex.stl"/-->
        <sphere radius="0.07"/>
      </geometry>
    </collision>
    <collision>
      <origin rpy="0 0 0" xyz="0 0.06 0.0"/>
      <geometry>
        <sphere radius="0.07"/>
      </geometry>
    </collision>
    <collision>
      <origin rpy="0.291 0 0" xyz="0 0.03 0.1"/>
      <geometry>
        <cylinder length="0.208" radius="0.07"/>
      </geometry>
    </collision>
  </link>
  <!-- Sixth element of the arm. z-axis -->
  <joint name="right_arm_4_joint" type="revolute">
    <origin rpy="0 0 0" xyz="0 0 0.20"/>
    <axis xyz="0 0 1"/>
    <limit effort="100" lower="-2.96705972839" upper="2.96705972839" velocity="3.56047167407"/>
    <dynamics damping="1.0" friction="10.0"/>
    <parent link="right_arm_4_link"/>
    <child link="right_arm_5_link"/>
  </joint>
  <joint name="right_arm_4_joint_stiffness" type="revolute">
    <axis xyz="0 0 1"/>
    <limit effort="0" lower="0" upper="5000" velocity="20000"/>
    <safety_controller k_position="30" k_velocity="30" soft_lower_limit="0" soft_upper_limit="5000"/>
    <parent link="right_arm_4_link"/>
    <child link="right_arm_5_link_dummy"/>
    <origin rpy="0 0 0"/>
  </joint>
  <link name="right_arm_5_link_dummy"/>
  <link name="right_arm_5_link">
    <inertial>
      <mass value="2.0"/>
      <origin rpy="0 0 0" xyz="0 0 0.124"/>
      <inertia ixx="0.0126506666667" ixy="0" ixz="0" iyy="0.003" iyz="0" izz="0.0108506666667"/>
    </inertial>
    <visual>
      <origin rpy="0 0 3.14159265359" xyz="0 0 -0.008"/>
      <geometry name="right_arm_5_geom">
        <mesh filename="package://lwr_description/meshes/link_5.STL"/>
      </geometry>
      <material name="Kuka/Orange"/>
    </visual>
    <collision>
      <origin rpy="0 0 0" xyz="0 0 0.0"/>
      <geometry>
        <!--mesh filename="package://lwr_description/meshes/convex/arm_segment_last_convex.stl"/-->
        <sphere radius="0.07"/>
      </geometry>
    </collision>
    <collision>
      <origin rpy="0 0 0" xyz="0 0.04 0.19"/>
      <geometry>
        <sphere radius="0.07"/>
      </geometry>
    </collision>
    <collision>
      <origin rpy="-0.207 0 0" xyz="0 0.02 0.095"/>
      <geometry>
        <cylinder length="0.198" radius="0.07"/>
      </geometry>
    </collision>
  </link>
  <!-- Seventh element of the arm. z-axis -->
  <joint name="right_arm_5_joint" type="revolute">
    <origin rpy="0 0 0" xyz="0 0 0.19"/>
    <axis xyz="0 -1 0"/>
    <limit effort="38" lower="-2.09439510239" upper="2.09439510239" velocity="3.21140582367"/>
    <dynamics damping="1.0" friction="10.0"/>
    <parent link="right_arm_5_link"/>
    <child link="right_arm_6_link"/>
  </joint>
  <joint name="right_arm_5_joint_stiffness" type="revolute">
    <axis xyz="0 0 1"/>
    <limit effort="0" lower="0" upper="5000" velocity="20000"/>
    <safety_controller k_position="30" k_velocity="30" soft_lower_limit="0" soft_upper_limit="5000"/>
    <parent link="right_arm_5_link"/>
    <child link="right_arm_6_link_dummy"/>
    <origin rpy="0 0 0"/>
  </joint>
  <link name="right_arm_6_link_dummy"/>
  <link name="right_arm_6_link">
    <inertial>
      <mass value="0.2"/>
      <origin rpy="0 0 0" xyz="0 0 0.0625"/>
      <inertia ixx="0.000520833333333" ixy="0" ixz="0" iyy="0.000520833333333" iyz="0" izz="0.000520833333333"/>
    </inertial>
    <visual>
      <origin rpy="0 0 3.14159265359" xyz="0 0 0"/>
      <geometry>
        <mesh filename="package://lwr_description/meshes/link_6.STL"/>
      </geometry>
      <material name="Kuka/Grey"/>
    </visual>
    <collision>
      <origin rpy="0 0 3.14159265359" xyz="0 0 0"/>
      <geometry>
        <mesh filename="package://lwr_description/meshes/convex/arm_wrist_convex.stl"/>
      </geometry>
    </collision>
  </link>
  <!-- Eighth element of the arm. z-axis -->
  <joint name="right_arm_6_joint" type="revolute">
    <origin rpy="0 0 0" xyz="0 0 0.078"/>
    <axis xyz="0 0 1"/>
    <limit effort="38" lower="-2.96705972839" upper="2.96705972839" velocity="3.21140582367"/>
    <dynamics damping="1.0" friction="10.0"/>
    <parent link="right_arm_6_link"/>
    <child link="right_arm_7_link"/>
  </joint>
  <joint name="right_arm_6_joint_stiffness" type="revolute">
    <axis xyz="0 0 1"/>
    <limit effort="0" lower="0" upper="5000" velocity="20000"/>
    <safety_controller k_position="30" k_velocity="30" soft_lower_limit="0" soft_upper_limit="5000"/>
    <parent link="right_arm_6_link"/>
    <child link="right_arm_7_link_dummy"/>
    <origin rpy="0 0 0"/>
  </joint>
  <link name="right_arm_7_link_dummy"/>
  <link name="right_arm_7_link">
    <inertial>
      <mass value="0.2"/>
      <origin xyz="0 0 0"/>
      <inertia ixx="0.0333333333333" ixy="0" ixz="0" iyy="0.0333333333333" iyz="0" izz="0.0333333333333"/>
    </inertial>
    <visual>
      <origin rpy="0 0 3.14159265359" xyz="0 0 0"/>
      <geometry>
        <mesh filename="package://lwr_description/meshes/link_7.STL"/>
      </geometry>
      <material name="Kuka/DarkGrey"/>
    </visual>
    <collision>
      <origin rpy="0 0 3.14159265359" xyz="0 0 0"/>
      <geometry>
        <cylinder length="0.05" radius="0.04"/>
      </geometry>
    </collision>
  </link>
  <gazebo>
    <plugin filename="liblwr_hw_gazebo_plugin.so" name="right_arm_lwr_hw_sim">
      <robotNamespace>right_arm</robotNamespace>
    </plugin>
  </gazebo>
  <gazebo reference="right_arm_base_link">
    <gravity>true</gravity>
    <material>Gazebo/Orange</material>
  </gazebo>
  <gazebo reference="right_arm_1_link">
    <gravity>true</gravity>
    <material>Gazebo/Orange</material>
  </gazebo>
  <gazebo reference="right_arm_2_link">
    <gravity>true</gravity>
    <material>Gazebo/Orange</material>
  </gazebo>
  <gazebo reference="right_arm_3_link">
    <gravity>true</gravity>
    <material>Gazebo/Orange</material>
  </gazebo>
  <gazebo reference="right_arm_4_link">
    <gravity>true</gravity>
    <material>Gazebo/Orange</material>
  </gazebo>
  <gazebo reference="right_arm_5_link">
    <gravity>true</gravity>
    <material>Gazebo/Orange</material>
  </gazebo>
  <gazebo reference="right_arm_6_link">
    <gravity>true</gravity>
    <material>Gazebo/Orange</material>
  </gazebo>
  <gazebo reference="right_arm_7_link">
    <gravity>true</gravity>
    <material>Gazebo/Grey</material>
  </gazebo>
  <transmission name="right_arm_0_trans">
    <type>transmission_interface/SimpleTransmission</type>
    <robotNamespace>right_arm</robotNamespace>
    <joint name="right_arm_0_joint">
      <hardwareInterface>PositionJointInterface</hardwareInterface>
      <hardwareInterface>EffortJointInterface</hardwareInterface>
    </joint>
    <actuator name="right_arm_0_motor">
      <mechanicalReduction>1</mechanicalReduction>
    </actuator>
  </transmission>
  <transmission name="right_arm_1_trans">
    <type>transmission_interface/SimpleTransmission</type>
    <robotNamespace>right_arm</robotNamespace>
    <joint name="right_arm_1_joint">
      <hardwareInterface>PositionJointInterface</hardwareInterface>
      <hardwareInterface>EffortJointInterface</hardwareInterface>
    </joint>
    <actuator name="right_arm_1_motor">
      <mechanicalReduction>1</mechanicalReduction>
    </actuator>
  </transmission>
  <transmission name="right_arm_2_trans">
    <type>transmission_interface/SimpleTransmission</type>
    <robotNamespace>right_arm</robotNamespace>
    <joint name="right_arm_2_joint">
      <hardwareInterface>PositionJointInterface</hardwareInterface>
      <hardwareInterface>EffortJointInterface</hardwareInterface>
    </joint>
    <actuator name="right_arm_2_motor">
      <mechanicalReduction>1</mechanicalReduction>
    </actuator>
  </transmission>
  <transmission name="right_arm_3_trans">
    <type>transmission_interface/SimpleTransmission</type>
    <robotNamespace>right_arm</robotNamespace>
    <joint name="right_arm_3_joint">
      <hardwareInterface>PositionJointInterface</hardwareInterface>
      <hardwareInterface>EffortJointInterface</hardwareInterface>
    </joint>
    <actuator name="right_arm_3_motor">
      <mechanicalReduction>1</mechanicalReduction>
    </actuator>
  </transmission>
  <transmission name="right_arm_4_trans">
    <type>transmission_interface/SimpleTransmission</type>
    <robotNamespace>right_arm</robotNamespace>
    <joint name="right_arm_4_joint">
      <hardwareInterface>PositionJointInterface</hardwareInterface>
      <hardwareInterface>EffortJointInterface</hardwareInterface>
    </joint>
    <actuator name="right_arm_4_motor">
      <mechanicalReduction>1</mechanicalReduction>
    </actuator>
  </transmission>
  <transmission name="right_arm_5_trans">
    <type>transmission_interface/SimpleTransmission</type>
    <robotNamespace>right_arm</robotNamespace>
    <joint name="right_arm_5_joint">
      <hardwareInterface>PositionJointInterface</hardwareInterface>
      <hardwareInterface>EffortJointInterface</hardwareInterface>
    </joint>
    <actuator name="right_arm_5_motor">
      <mechanicalReduction>1</mechanicalReduction>
    </actuator>
  </transmission>
  <transmission name="right_arm_6_trans">
    <type>transmission_interface/SimpleTransmission</type>
    <robotNamespace>right_arm</robotNamespace>
    <joint name="right_arm_6_joint">
      <hardwareInterface>PositionJointInterface</hardwareInterface>
      <hardwareInterface>EffortJointInterface</hardwareInterface>
    </joint>
    <actuator name="right_arm_6_motor">
      <mechanicalReduction>1</mechanicalReduction>
    </actuator>
  </transmission>
  <joint name="left_gripper_base_joint" type="fixed">
    <parent link="left_arm_7_link"/>
    <child link="left_gripper_base_link"/>
    <origin rpy="0 0 0" xyz="0 0 0"/>
  </joint>
  <!--     PALM -->
  <link name="left_gripper_base_link">
    <visual>
      <geometry>
        <mesh filename="package://schunk_pg70/meshes/pg70.dae"/>
      </geometry>
      <material name="blue">
        <color rgba="0 0 1 1"/>
      </material>
    </visual>
    <collision>
      <geometry>
        <mesh filename="package://schunk_pg70/meshes/pg70.dae"/>
      </geometry>
      <material name="blue"/>
    </collision>
  </link>
  <!-- LEFT FINGER BASE -->
  <joint name="left_gripper_finger_left_joint" type="prismatic">
    <parent link="left_gripper_base_link"/>
    <child link="left_gripper_finger_left_link"/>
    <limit effort="100" lower="-0.001" upper="0.04" velocity="2.0"/>
    <origin rpy="0 0 0" xyz="0 0 0.0789"/>
    <axis xyz="0 1 0"/>
  </joint>
  <link name="left_gripper_finger_left_link">
    <visual>
      <geometry>
        <box size="0.03 0.01 0.01"/>
      </geometry>
      <material name="black">
        <color rgba="0 0 0 1"/>
      </material>
    </visual>
    <collision>
      <geometry>
        <box size="0.03 0.01 0.01"/>
      </geometry>
      <material name="black"/>
    </collision>
  </link>
  <!-- LEFT FINGERTIP -->
  <joint name="left_gripper_fingertip_left_joint" type="fixed">
    <parent link="left_gripper_finger_left_link"/>
    <child link="left_gripper_fingertip_left_link"/>
    <origin rpy="0 0 0" xyz="0 0.01 0.045"/>
  </joint>
  <link name="left_gripper_fingertip_left_link">
    <visual>
      <geometry>
        <box size="0.03 0.01 0.1"/>
      </geometry>
      <material name="silver">
        <color rgba="0.8 0.8 0.8 1"/>
      </material>
    </visual>
    <collision>
      <geometry>
        <box size="0.03 0.01 0.1"/>
      </geometry>
      <material name="black"/>
    </collision>
  </link>
  <!-- RIGHT FINGER BASE -->
  <joint name="left_gripper_finger_right_joint" type="prismatic">
    <mimic joint="left_gripper_finger_left_joint" multiplier="1" offset="0"/>
    <parent link="left_gripper_base_link"/>
    <child link="left_gripper_finger_right_link"/>
    <limit effort="100" lower="-0.001" upper="0.04" velocity="2.0"/>
    <origin rpy="-0 0 0" xyz="0 0 0.0789"/>
    <axis xyz="0 -1 0"/>
  </joint>
  <link name="left_gripper_finger_right_link">
    <visual>
      <geometry>
        <box size="0.03 0.01 0.01"/>
      </geometry>
      <material name="black"/>
    </visual>
    <collision>
      <geometry>
        <box size="0.03 0.01 0.01"/>
      </geometry>
      <material name="black"/>
    </collision>
  </link>
  <!-- RIGHT FINGERTIP -->
  <joint name="left_gripper_fingertip_right_joint" type="fixed">
    <parent link="left_gripper_finger_right_link"/>
    <child link="left_gripper_fingertip_right_link"/>
    <origin rpy="0 0 0" xyz="0 -0.01 0.045"/>
  </joint>
  <link name="left_gripper_fingertip_right_link">
    <visual>
      <geometry>
        <box size="0.03 0.01 0.1"/>
      </geometry>
      <material name="silver"/>
    </visual>
    <collision>
      <geometry>
        <box size="0.03 0.01 0.1"/>
      </geometry>
      <material name="black"/>
    </collision>
  </link>
  <joint name="right_gripper_base_joint" type="fixed">
    <parent link="right_arm_7_link"/>
    <child link="right_gripper_base_link"/>
    <origin rpy="0 0 0" xyz="0 0 0"/>
  </joint>
  <!--     PALM -->
  <link name="right_gripper_base_link">
    <visual>
      <geometry>
        <mesh filename="package://schunk_pg70/meshes/pg70.dae"/>
      </geometry>
      <material name="blue">
        <color rgba="0 0 1 1"/>
      </material>
    </visual>
    <collision>
      <geometry>
        <mesh filename="package://schunk_pg70/meshes/pg70.dae"/>
      </geometry>
      <material name="blue"/>
    </collision>
  </link>
  <!-- LEFT FINGER BASE -->
  <joint name="right_gripper_finger_left_joint" type="prismatic">
    <parent link="right_gripper_base_link"/>
    <child link="right_gripper_finger_left_link"/>
    <limit effort="100" lower="-0.001" upper="0.04" velocity="2.0"/>
    <origin rpy="0 0 0" xyz="0 0 0.0789"/>
    <axis xyz="0 1 0"/>
  </joint>
  <link name="right_gripper_finger_left_link">
    <visual>
      <geometry>
        <box size="0.03 0.01 0.01"/>
      </geometry>
      <material name="black">
        <color rgba="0 0 0 1"/>
      </material>
    </visual>
    <collision>
      <geometry>
        <box size="0.03 0.01 0.01"/>
      </geometry>
      <material name="black"/>
    </collision>
  </link>
  <!-- LEFT FINGERTIP -->
  <joint name="right_gripper_fingertip_left_joint" type="fixed">
    <parent link="right_gripper_finger_left_link"/>
    <child link="right_gripper_fingertip_left_link"/>
    <origin rpy="0 0 0" xyz="0 0.01 0.045"/>
  </joint>
  <link name="right_gripper_fingertip_left_link">
    <visual>
      <geometry>
        <box size="0.03 0.01 0.1"/>
      </geometry>
      <material name="silver">
        <color rgba="0.8 0.8 0.8 1"/>
      </material>
    </visual>
    <collision>
      <geometry>
        <box size="0.03 0.01 0.1"/>
      </geometry>
      <material name="black"/>
    </collision>
  </link>
  <!-- RIGHT FINGER BASE -->
  <joint name="right_gripper_finger_right_joint" type="prismatic">
    <mimic joint="right_gripper_finger_left_joint" multiplier="1" offset="0"/>
    <parent link="right_gripper_base_link"/>
    <child link="right_gripper_finger_right_link"/>
    <limit effort="100" lower="-0.001" upper="0.04" velocity="2.0"/>
    <origin rpy="-0 0 0" xyz="0 0 0.0789"/>
    <axis xyz="0 -1 0"/>
  </joint>
  <link name="right_gripper_finger_right_link">
    <visual>
      <geometry>
        <box size="0.03 0.01 0.01"/>
      </geometry>
      <material name="black"/>
    </visual>
    <collision>
      <geometry>
        <box size="0.03 0.01 0.01"/>
      </geometry>
      <material name="black"/>
    </collision>
  </link>
  <!-- RIGHT FINGERTIP -->
  <joint name="right_gripper_fingertip_right_joint" type="fixed">
    <parent link="right_gripper_finger_right_link"/>
    <child link="right_gripper_fingertip_right_link"/>
    <origin rpy="0 0 0" xyz="0 -0.01 0.045"/>
  </joint>
  <link name="right_gripper_fingertip_right_link">
    <visual>
      <geometry>
        <box size="0.03 0.01 0.1"/>
      </geometry>
      <material name="silver"/>
    </visual>
    <collision>
      <geometry>
        <box size="0.03 0.01 0.1"/>
      </geometry>
      <material name="black"/>
    </collision>
  </link>
</robot>
