<?xml version="1.0" ?>
<!-- =================================================================================== -->
<!-- |    This document was autogenerated by xacro from y_dummy.xacro                  | -->
<!-- |    EDITING THIS FILE BY HAND IS NOT RECOMMENDED                                 | -->
<!-- =================================================================================== -->
<robot name="rosemarie" xmlns:xacro="http://www.ros.org/wiki/xacro">
  <link name="root_link">

  </link>
  <joint name="root_joint" type="continuous">
    <origin rpy="0 0 0" xyz="0 0 1"/>
    <parent link="root_link"/>
    <child link="link1"/>
  </joint>
  <link name="link1">
    <inertial>
      <mass value="1"/>
      <origin xyz="0 0 0"/>
      <inertia ixx="0.01" ixy="0.0" ixz="0.0" iyy="0.01" iyz="0.0" izz="0.01"/>
    </inertial>
  </link>
  <joint name="joint_1_2" type="continuous">
    <origin rpy="0 0 0" xyz="0 0 1"/>
    <parent link="link1"/>
    <child link="link2"/>
  </joint>
  <link name="link2">
    <inertial>
      <mass value="1"/>
      <origin xyz="0 0 0"/>
      <inertia ixx="0.01" ixy="0.0" ixz="0.0" iyy="0.01" iyz="0.0" izz="0.01"/>
    </inertial>
  </link>
  <joint name="joint_1_3" type="continuous">
    <origin rpy="0 0 0" xyz="0 0 1"/>
    <parent link="link1"/>
    <child link="link3"/>
  </joint>
  <link name="link3">
    <inertial>
      <mass value="1"/>
      <origin xyz="0 0 0"/>
      <inertia ixx="0.01" ixy="0.0" ixz="0.0" iyy="0.01" iyz="0.0" izz="0.01"/>
    </inertial>
  </link>
  <joint name="joint_2_4" type="continuous">
    <origin rpy="0 0 0" xyz="0 0 1"/>
    <parent link="link2"/>
    <child link="link4"/>
  </joint>
  <link name="link4">
    <inertial>
      <mass value="1"/>
      <origin xyz="0 0 0"/>
      <inertia ixx="0.01" ixy="0.0" ixz="0.0" iyy="0.01" iyz="0.0" izz="0.01"/>
    </inertial>
  </link>
  <joint name="joint_4_5" type="continuous">
    <origin rpy="0 0 0" xyz="0 0 1"/>
    <parent link="link4"/>
    <child link="link5"/>
  </joint>
  <link name="link5">
    <inertial>
      <mass value="1"/>
      <origin xyz="0 0 0"/>
      <inertia ixx="0.01" ixy="0.0" ixz="0.0" iyy="0.01" iyz="0.0" izz="0.01"/>
    </inertial>
  </link>
  <joint name="joint_3_6" type="continuous">
    <origin rpy="0 0 0" xyz="0 0 1"/>
    <parent link="link3"/>
    <child link="link6"/>
  </joint>
  <link name="link6">
    <inertial>
      <mass value="1"/>
      <origin xyz="0 0 0"/>
      <inertia ixx="0.01" ixy="0.0" ixz="0.0" iyy="0.01" iyz="0.0" izz="0.01"/>
    </inertial>
  </link>
  <joint name="joint_3_7" type="continuous">
    <origin rpy="0 0 0" xyz="0 0 1"/>
    <parent link="link3"/>
    <child link="link7"/>
  </joint>
  <link name="link7">
    <inertial>
      <mass value="1.01"/>
      <origin xyz="0 0 0"/>
      <inertia ixx="0.01" ixy="0.0" ixz="0.0" iyy="0.01" iyz="0.0" izz="0.01"/>
    </inertial>
  </link>
  <joint name="joint_2_8" type="continuous">
    <origin rpy="0 0 0" xyz="0 0 1"/>
    <parent link="link2"/>
    <child link="link8"/>
  </joint>
  <link name="link8">
    <inertial>
      <mass value="1.01"/>
      <origin xyz="0 0 0"/>
      <inertia ixx="0.01" ixy="0.0" ixz="0.0" iyy="0.01" iyz="0.0" izz="0.01"/>
    </inertial>
  </link>
</robot>

